{"stats": {"errors": 1, "failures": 4, "passes": 2, "skipped": 0, "encoding": "UTF-8", "total": 7}, "results": [{"classname": "index_test:TestPythonLists", "name": "test_italy", "time": 0.0006287097930908203, "type": "failure", "errtype": "builtins.AssertionError", "message": "None != 'Italy'", "tb": "Traceback (most recent call last):\n  File \"/opt/conda/lib/python3.6/site-packages/unittest2/case.py\", line 67, in testPartExecutor\n    yield\n  File \"/opt/conda/lib/python3.6/site-packages/unittest2/case.py\", line 625, in run\n    testMethod()\n  File \"/home/yoyothesheep/python-lists-lab-data-science/test/index_test.py\", line 7, in test_italy\n    self.assertEqual(italy, 'Italy')\n  File \"/opt/conda/lib/python3.6/site-packages/unittest2/case.py\", line 836, in assertEqual\n    assertion_func(first, second, msg=msg)\n  File \"/opt/conda/lib/python3.6/site-packages/unittest2/case.py\", line 829, in _baseAssertEqual\n    raise self.failureException(msg)\nAssertionError: None != 'Italy'\n"}, {"classname": "index_test:TestPythonLists", "name": "test_kindof_neighbors", "time": 0.00030303001403808594, "type": "failure", "errtype": "builtins.AssertionError", "message": "None != ['USA', 'Argentina', 'Mexico', 'USA']", "tb": "Traceback (most recent call last):\n  File \"/opt/conda/lib/python3.6/site-packages/unittest2/case.py\", line 67, in testPartExecutor\n    yield\n  File \"/opt/conda/lib/python3.6/site-packages/unittest2/case.py\", line 625, in run\n    testMethod()\n  File \"/home/yoyothesheep/python-lists-lab-data-science/test/index_test.py\", line 13, in test_kindof_neighbors\n    self.assertEqual(kindof_neighbors, ['USA', 'Argentina', 'Mexico', 'USA'])\n  File \"/opt/conda/lib/python3.6/site-packages/unittest2/case.py\", line 836, in assertEqual\n    assertion_func(first, second, msg=msg)\n  File \"/opt/conda/lib/python3.6/site-packages/unittest2/case.py\", line 829, in _baseAssertEqual\n    raise self.failureException(msg)\nAssertionError: None != ['USA', 'Argentina', 'Mexico', 'USA']\n"}, {"classname": "index_test:TestPythonLists", "name": "test_malta_presence", "time": 0.00017118453979492188, "type": "success"}, {"classname": "index_test:TestPythonLists", "name": "test_mexico", "time": 0.0001850128173828125, "type": "failure", "errtype": "builtins.AssertionError", "message": "None != 'Mexico'", "tb": "Traceback (most recent call last):\n  File \"/opt/conda/lib/python3.6/site-packages/unittest2/case.py\", line 67, in testPartExecutor\n    yield\n  File \"/opt/conda/lib/python3.6/site-packages/unittest2/case.py\", line 625, in run\n    testMethod()\n  File \"/home/yoyothesheep/python-lists-lab-data-science/test/index_test.py\", line 10, in test_mexico\n    self.assertEqual(mexico, 'Mexico')\n  File \"/opt/conda/lib/python3.6/site-packages/unittest2/case.py\", line 836, in assertEqual\n    assertion_func(first, second, msg=msg)\n  File \"/opt/conda/lib/python3.6/site-packages/unittest2/case.py\", line 829, in _baseAssertEqual\n    raise self.failureException(msg)\nAssertionError: None != 'Mexico'\n"}, {"classname": "index_test:TestPythonLists", "name": "test_new_mexico_presence", "time": 0.0001163482666015625, "type": "success"}, {"classname": "index_test:TestPythonLists", "name": "test_num_repeats", "time": 0.00020051002502441406, "type": "failure", "errtype": "builtins.AssertionError", "message": "None != 3", "tb": "Traceback (most recent call last):\n  File \"/opt/conda/lib/python3.6/site-packages/unittest2/case.py\", line 67, in testPartExecutor\n    yield\n  File \"/opt/conda/lib/python3.6/site-packages/unittest2/case.py\", line 625, in run\n    testMethod()\n  File \"/home/yoyothesheep/python-lists-lab-data-science/test/index_test.py\", line 25, in test_num_repeats\n    self.assertEqual(num_of_repeats, 3)\n  File \"/opt/conda/lib/python3.6/site-packages/unittest2/case.py\", line 836, in assertEqual\n    assertion_func(first, second, msg=msg)\n  File \"/opt/conda/lib/python3.6/site-packages/unittest2/case.py\", line 829, in _baseAssertEqual\n    raise self.failureException(msg)\nAssertionError: None != 3\n"}, {"classname": "index_test:TestPythonLists", "name": "test_unique_countries", "time": 0.0002338886260986328, "type": "error", "errtype": "builtins.TypeError", "message": "'NoneType' object is not iterable", "tb": "Traceback (most recent call last):\n  File \"/opt/conda/lib/python3.6/site-packages/unittest2/case.py\", line 1173, in assertItemsEqual\n    actual = sorted(actual_seq)\nTypeError: 'NoneType' object is not iterable\n\nDuring handling of the above exception, another exception occurred:\n\nTraceback (most recent call last):\n  File \"/opt/conda/lib/python3.6/site-packages/unittest2/case.py\", line 67, in testPartExecutor\n    yield\n  File \"/opt/conda/lib/python3.6/site-packages/unittest2/case.py\", line 625, in run\n    testMethod()\n  File \"/home/yoyothesheep/python-lists-lab-data-science/test/index_test.py\", line 22, in test_unique_countries\n    self.assertItemsEqual(['Argentina', 'Canada', 'Croatia', 'Finland', 'Italy', 'Malta', 'Mexico', 'Morocco', 'South Korea', 'USA'], unique_countries)\n  File \"/opt/conda/lib/python3.6/site-packages/unittest2/case.py\", line 1177, in assertItemsEqual\n    actual = list(actual_seq)\nTypeError: 'NoneType' object is not iterable\n"}]}